Workbook

Sheet Form Responses 1
A1: Timestamp | B1: Community Manager's Name | C1: Country | D1: Artwork Type | E1: Key Message | F1: Reference Material: (Link to reference if possible) | G1: Deadline: (Expected Date of delivery) | H1: Status of Delivery | I1: Link to Artwork - GoldPari - Artwork Delivery Drive | J1: Approved
A2: 45524.112 | B2: Gideon Benyin-Amo | C2: Ghana | D2: Social Media Post | E2: Good Morning, Ghana! Another day, another chance to win big with Gold Pari. #GoldPari #Welcome | F2: N/A | G2: 45525
A3: 45524.61 | B3: Oji Chimemela Ude | C3: Nigeria | D3: Social Media Post | E3: Hello Goldpari community! We're excited to share updates, behind-the-scenes insights, and exclusive offers with you! Stay tuned and let us know what you love about Goldpari! | F3: N/A | G3: 45525
A4: 45524.624 | B4: Gideon Benyin-Amo | C4: Ghana | D4: Social Media Post | E4: Get the best odds for Champions league Qualifiers today on Gold Pari | F4: N/A | G4: 45525
A5: 45524.938 | B5: Lawrence | C5: Uganda | D5: Whatsapp Post | E5: Earn Money Online as a GoldPari Partner Join the GoldPari Affiliate Program Refer new users to GoldPari Earn up to 40% commission on referrals Sign Up Today! | F5: https://goldpari.partners/ | G5: 45524
A6: 45524.94 | B6: Matthew Opio | C6: Uganda | D6: Social Media Post | E6: Welcome to Gold Pari | F6: N/A | G6: 45525
A7: 45524.941 | B7: Lawrence | C7: Uganda | D7: Whatsapp Post | E7: Why Become a GoldPari Partner? - Regular Payouts Receive automatic weekly payments, starting at $30. - High Commission Rates Earn up to 40% commission on every customer you refer. Sign Up Today! | F7: https://goldpari.partners/ | G7: 45524
A8: 45524.945 | B8: Lawrence | C8: Uganda | D8: Whatsapp Post | E8: Our Affiliates Earn an Average of $935/Month Start earning today! | F8: https://goldpari.partners/ | G8: 45524
A9: 45524.951 | B9: Lawrence | C9: Uganda | D9: Whatsapp Post | E9: Getting Started is Easy! **** Show the affiliate registration page here - https://goldpari.partners/sign-up Start Earning Today! | F9: https://aff.ninja/wp-content/uploads/2024/02/Partners-1xBet-Registration-1024x462.webp | G9: 45524
A10: 45524.967 | B10: Lawrence | C10: Uganda | D10: Whatsapp Post | E10: Unlock Your 300% Welcome Bonus! Sign Up Today on GoldPari. Complete Your Profile in My Account. Deposit as Little as 3800 UGX to qualify. Triple Your Deposit with a 300% bonus, up to 750,000 UGX! Register Now. T&C Apply. | F10: https://goldpari.com/bonus/rules/1st-300 | G10: 45524
A11: 45524.971 | B11: Lawrence | C11: Uganda | D11: Whatsapp Post | E11: Funa 3% Cashback Buli Wiiki! Weewandiise oba Yingira ku GoldPari website oba app. Betting buli lunaku, wiiki yonna. Funa 3% y'ebyo by'olwaanye ebitali bitojja okutuuka ku 3,713,846 UGX direct ku account yo buli Lwokubiri. Weewandiise Kati! | F11: https://goldpari.com/bonus/rules/3_percent_weekly_cashback | G11: 45524
A12: 45524.974 | B12: Lawrence | C12: Uganda | D12: Whatsapp Post | E12: Get Ahead with Advancebet! Unlock extra betting power with our exclusive Advancebet bonus, available for customers with unsettled bets in their accounts. Take your chances and place new bets even before your current ones settle! Bet Now & Win Big! | F12: https://goldpari.com/bonus/rules/doverie | G12: 45524
A13: 45524.976 | B13: Lawrence | C13: Uganda | D13: Whatsapp Post | E13: Celebrate Your Birthday with Goldpari! Is it your special day? We want to wish you a Happy Birthday and give you a personal bonus to make your celebration even better! Claim Your Birthday Gift Now and Start Playing! | F13: https://goldpari.com/bonus/rules/birthday | G13: 45524
... A98: 45582.627 | B98: Justin Chansa | C98: Zambia | D98: Banners | E98: Kindly prepare banners for me. On all primer league matchs. From 19th to 22se of October | F98: Nil | G98: 45583

Sheet Topline details 
A1: Community Insights and Trends
A2: WhatsApp:
A3: - Engagement rate: 20% - 30% (higher than average due to personalized content)
A4: - Average group size: 200 - 500 members
A5: - Most popular content types:
A6: - Sports updates (60% engagement)
A7: - Promotions and offers (40% engagement)
A8: - News and updates (30% engagement)
A10: Top-performing groups:
A11: - Sports Fanatics (300 members, 35% engagement)
A12: - Betters United(250 members, 28% engagement)
A14: Telegram:
... A142: Pros: Provides localized expertise and tailored strategies for each market. Allows for deeper understanding of regional dynamics and affiliate needs.

Sheet Weekly Metrics
A1: Country | B1: KPIs | C1: Monday | D1: Monday | E1: Monday | F1: Monday | G1: Monday | H1: Monday | I1: Monday | J1: Monday | K1: Monday | L1: Monday | M1: Monday | N1: Monday | O1: Monday | P1: Acquired | Q1: Targets | R1: Overview
C2: 45516 | D2: 45523 | E2: 45530 | F2: 45537 | G2: 45634 | H2: 19/08/24 | I2: 26/08/24 | J2: 45331 | K2: 45544 | L2: 16/09/24 | M2: 23/09/24 | N2: 30/09/24 | O2: 45483
A3: Uganda | B3: WhatsApp group membership to (500) | C3: 0 | D3: 9 | P3: =sum(C3:O3) -> 9 | Q3: 500 | R3: =Q3-P3 -> 491
B4: Telegram channel subscribers to (2,000) | C4: 0 | D4: 0 | P4: =sum(C4:O4) -> 0 | Q4: 2000 | R4: =Q4-P4 -> 2000
B5: Average engagement rate: 15% across both platforms | C5: 0 | D5: - | P5: =sum(C5:O5) -> 0 | Q5: 0.15
A6: Ghana | B6: WhatsApp group membership to (500) | C6: 0 | D6: 16 | P6: =sum(C6:O6) -> 16 | Q6: 500 | R6: =Q6-P6 -> 484
B7: Telegram fan group subscribers to (2,000) | C7: 0 | D7: 11 | P7: =sum(C7:O7) -> 11 | Q7: 2000 | R7: =Q7-P7 -> 1989
B8: Average engagement rate: 15% across both platforms | C8: 0 | P8: =sum(C8:O8) -> 0 | Q8: 0.15
A9: Nigeria | B9: WhatsApp group membership to (500) | C9: 0 | D9: 50 | P9: =sum(C9:O9) -> 50 | Q9: 500 | R9: =Q9-P9 -> 450
B10: Telegram channel subscribers to (2,000) | C10: 0 | D10: 128 | P10: =sum(C10:O10) -> 128 | Q10: 2000 | R10: =Q10-P10 -> 1872
B11: Average engagement rate: 15% across both platforms | C11: 0 | D11: - | P11: =sum(C11:O11) -> 0 | Q11: 0.15
A12: Zambia | B12: WhatsApp group membership to (500) | C12: 0 | D12: 0 | P12: =sum(C12:O12) -> 0 | Q12: 500 | R12: =Q12-P12 -> 500
B13: Telegram channel subscribers to (2,000) | C13: 0 | D13: 0 | P13: =sum(C13:O13) -> 0 | Q13: 2000
B14: Average engagement rate: 15% across both platforms | C14: 0 | D14: 0 | P14: =sum(C14:O14) -> 0 | Q14: 0.15

Sheet Publishing Calendar UG
A1: Date | B1: Day | C1: Platform | D1: Content Type | E1: Post Description | F1: Content Creator | G1: Status | H1: Approval Date | I1: Publishing Time | J1: Link to Content | K1: Media File Link | L1: Notes
A2: Thursday 15th August | B2: Thursday | C2: Whatsapp & Telegram | D2: Video | E2: 1. Welcome Post (Morning) COPY IN IMAGE Welcome to Gold Pari IMAGE DESCRIPTION Image showing something Gold Pari fresh and new CAPTION Welcome to the Gold Pari community! We’re thrilled to have you here. Get ready for exciting opportunities, insider tips, and big wins! Start by visiting Gold Pari](https://goldpari.com/ and signing up to join the winning league.
B3: Thursday | C3: Whatsapp & Telegram | D3: Image | E3: 2. Awareness Post (Midday) COPY IN IMAGE Become a betting expert with Gold Pari IMAGE DESCRIPTION Someone thinking while placing a bet on the Gold Pari Site CAPTION New to betting? Gold Pari makes it easy to get started! Check out our user-friendly platform https://goldpari.com/ and discover how you can start winning today.
B4: Thursday | C4: Whatsapp & Telegram | D4: Image | E4: 3. Engagement Post (Afternoon) COPY IN IMAGE What’s your favourite sport to bet on? IMAGE DESCRIPTION A video of different games rolling CAPTION What’s your favorite sport to bet on? Let’s hear it in the comments! Share your picks and connect with other like minded people.
B5: Thursday | C5: Whatsapp & Telegram | D5: Image | E5: 4. Education Post (Evening) HEADER Gold Pari Tips BODY COPY 1. Start Small 2. Do Your Research 3. Diversify Your Bets 4. Set a Budget 5. Avoid Emotional Betting: CAPTION Pro Tip: Always start with small bets to get a feel for the game. Learn more about smart betting strategies and visit https://goldpari.com/ to make your first deposit today
A7: Friday 15th August | B7: Friday | C7: Whatsapp & Telegram | D7: Image | E7: 1. Welcome Post (Afternoon) COPY IN IMAGE Welcome to the family IMAGE DESCRIPTION Group of people happy together CAPTION A warm welcome to all our new members! You’re now part of the Gold Pari family. Head over to https://goldpari.com/ and kickstart your betting journey with us.
C8: Whatsapp & Telegram | D8: Video | E8: 2. Soccer post COPYINVIDEO Premier league is back. Today is the day. IMAGE DESCRIPTION Premier League La liga Ligue 1 Premeira Liga CAPTION Gameweek 1of 38 of the premier league starts today. Don,t forget to visit https://goldpari.com/ to place your bet.
C9: Whatsapp & Telegram | D9: Image | E9: 3. Betting odds COPY IN IMAGE Leero gwe awangula IMAGE DESCRIPTION The selected days game with odds CAPTION Our odds are your best chance to win
C10: Whatsapp & Telegram | D10: Images | E10: 4. Game updates Team Lineup updates Score updates.
A11: Saturday 16th Aug Friday | B11: Saturday
B12: Saturday
B13: Saturday
B14: Saturday

Sheet Publishing Calendar - Ghana
A1: Date | B1: Day | C1: Platform | D1: Content Type | E1: Post Description | F1: Content Creator | G1: Status | H1: Approval Date | I1: Publishing Time | J1: Link to Content | K1: Media File Link | L1: Notes
A2: 15th August | B2: Thursday | C2: Whatsapp & Telegram | D2: Image | E2: 1. Welcome Post (Morning) COPY IN IMAGE Good Morning, Ghana! Start your day with excitement—Gold Pari is here! Ready to turn your passion for sports into winnings? Join us now for the ultimate betting experience. #GoldPari #BetOnWinning" IMAGE DESCRIPTION A vibrant sunrise over Accra, with a dynamic overlay of Gold Pari's logo and a football in motion, symbolizing the start of a thrilling journey. CAPTION Rise and shine, Ghana! 🌞 Gold Pari is here to kickstart your winning streak. Are you ready to bet on your passion? Start by visiting Gold Pari](https://goldpari.com/ and signing up to join the winning league.
B3: Thursday | D3: Image | E3: 2. Awareness Post (Midday) COPY IN IMAGE Lunchtime vibes! 🍔 Take a break and dive into the world of sports betting with Gold Pari. Big wins await you—are you in? #GoldPari #BettingMadeEasy IMAGE DESCRIPTION A lunchtime scene at a local Ghanaian restaurant, with friends enjoying a meal while checking their phones, the Gold Pari app visible on the screen. CAPTION Midday thrill! As you enjoy your lunch, why not spice up your day with some winning bets? Join Gold Pari now and make every moment count! 🔗 [Insert Sign-Up Link] #GoldPari #LunchBreak #WinningStreak
B4: Thursday | D4: Image | E4: 3. Engagement Post (Afternoon) COPY IN IMAGE What’s your favourite sport to bet on? IMAGE DESCRIPTION A dynamic image of a footballer mid-kick, with a subtle background of various sports icons, showcasing the variety of sports available on Gold Pari. CAPTION What’s your favorite sport to bet on? Let’s hear it in the comments! Share your picks and connect with other like minded people. #GoldPari #AfternoonHustle
B5: Thursday | D5: Image | E5: 4. Education Post (Evening) HEADER Gold Pari Tips BODY COPY 1. Start Small 2. Do Your Research 3. Diversify Your Bets 4. Set a Budget 5. Avoid Emotional Betting: CAPTION Pro Tip: Always start with small bets to get a feel for the game. Learn more about smart betting strategies and visit https://goldpari.com/ to make your first deposit today#GoldPari #EveningWins #NightBetting
A7: 16th August | B7: Friday | C7: Whatsapp & Telegram | D7: Image | E7: 1. Awareness Post (Morning COPY IN IMAGE: Good Morning, Ghana! 🌞 Premier League action is back Today! Manchester United vs Fulham. #GoldPari #PremierLeague IAMGE DESCRIPSTION:EPL is Back, with Machester vs Fulham match displayed CAPTION: The Premier League is back! ⚽ Bet on Machester vs Fulham and get in on the action with Gold Pari. #GoldPari #EPL" via (https://goldpari.com/)
D8: Image | E8: 2. Betting odds (Midday) COPY IN IMAGE Get the best odds on Gold Pari IMAGE DESCRIPTION The selected selected odds of the big leagues CAPTION Our odds are your best chance to win #GoldPari #BestOdds
D9: Image | E9: 3. Engagement Post (Afternoon) COPY IN IMAGE To score the First EPL goal IMAGE DECRIPTION: Image of EPL match of Manchester United vs Fulham with some selected players from each team CAPTION: Who is going to score the first goal of this season EPL? #GoldPari #EPL #FirstGoal
D10: Images | E10: 4. Game updates (Evening) COPY IN IMAGE Team Lineup updates of Manchester United vs Fulham CAPTION: Check out the lineup of tonight's EPL match between Manchester United and Fulham #GoldPari #EPL
A12: 17th August | B12: Saturday | C12: Whatsapp & Telegram | D12: Image | E12: 1. Welcone Post (Morning) COPY IN IMAGE: Good Morning, Ghana! Ready for another winning day with Gold Pari? Let’s go! #GoldPari #Welcome IMAGE DECRIPTION: A vibrant welcome image with the Gold Pari logo and happy bettors CAPTION: Start your day with Gold Pari! Let’s win together. [https://goldpari.com] #GoldPari #Welcome
D13: Image | E13: 2. Engagement Post (Midday) COPY IN IMAGE: Afternoon trivia! Who won the Ballon d'Or in 2023? Comment and let's have fun #GoldPari #FootballTrivia IMAGE DECRIPTION: A quiz card with a question about the Ballon d'Or winner. CAPTION: Test your football knowledge! Answer and show off your ball knowledge. #GoldPari #QuizTime
D14: Image | E14: 3.Football Post (Afternoon) COPY IN IMAGE: EPL action today—don’t miss it! Who’s your pick? #GoldPari #EPL IMAGE DECRIPTION: An action shot of EPL players during a match CAPTION: Bet on today’s EPL match! Bet now with Gold Pari. [https://goldpari.com] #GoldPari #EPL
D15: Image | E15: 4. Game Updates (Evening) COPY IN IMAGE: Get the latest updates from today’s big match. Who’s leading? #GoldPari #GameUpdates IMAGE DECRIPTION: A live scoreboard or image from the ongoing match CAPTION: Stay updated on today’s match. [https://goldpari.com/] #GoldPari #GameUpdates
A17: 18th August | B17: Sunday | C17: Whatsapp & Telegram | D17: Image | E17: 1. Welcome Post (Morning) COPY IN IMAGE: Good Morning, Ghana! Join us today and start winning with Gold Pari [https://goldpari.com/]. #GoldPari #Welcome IMAGE DECRIPTION: A warm welcome image with the Gold Pari logo. CAPTION: Start your day with Gold Pari! Join the fun. [https://goldpari.com/] #GoldPari #Welcome"
D18: Image | E18: 2. Football Post (Midday) COPY IN IMAGE: EPL match of the day! Chelsea vs Manchester City #GoldPari #EPL IMAGE DECRIPTION: an image of a chelsea player (Palmer) against Manchester City player (Haaland) CAPTION: Bet on today’s Premier League matches! Join the action with Gold Pari. [https://goldpari.com/] #GoldPari #EPL"
D19: Image | E19: 3. Betting Odds (Afternoon) COPY IN IMAGE: Check the latest odds for tonight’s top matches! #GoldPari #BettingOdds IMAGE DECRIPTION: A visual display of betting odds CAPTION: Bet on today’s top matches! Bet now with Gold Pari.[https://goldpari.com/] #GoldPari #BettingOdds
D20: Image | E20: 4. Game Updates (Evening) COPY IN IMAGE: Stay updated on today's top matches #GoldPari #GameUpdates IMAGE DECRIPTION: A live scoreboard or image from the ended matches of the top leagues CAPTION: Get updates on tonight’s matches. #GoldPari #GameUpdates
A22: 19th August | B22: Monday | C22: Whatsapp & Telegram | D22: Image | E22: 1. Welcome Post (Morning) COPY IN IMAGE: Good Morning, Ghana! Join us today and start winning with Gold Pari [https://goldpari.com/]. #GoldPari #Welcome IMAGE DECRIPTION: A warm welcome image with the Gold Pari logo. CAPTION: Start your day with Gold Pari! Join the fun. [https://goldpari.com/] #GoldPari #Welcome"
D23: Image | E23: 2. Engagement Post (Afternoon) COPY IN IMAGE: Afternoon trivia! Who scored the most goals in the 2023/2024 UEFA Champions League? #GoldPari #FootballTrivia IMAGE DECRIPTION: A quiz card with a question about the top scorer in the 2023/2024 UEFA Champions League CAPTION: Test your football knowledge! Let's meet at the comment section and have fun #GoldPari #QuizTime
D24: Image | E24: 3. Game Updates (Evening) COPY IN IMAGE: Stay updated on today's top matches #GoldPari #GameUpdates IMAGE DECRIPTION: A live scoreboard or image from the ended matches of the top leagues CAPTION: Get updates on tonight’s matches. #GoldPari #GameUpdates
A26: 20th August | B26: Tuesday | C26: Whatsapp & Telegram | D26: Image | E26: 1. Post (Morning) COPY IN IMAGE: Good Morning, Ghana! Welcome to Gold Pari! Start betting today and let the wins begin. #GoldPari #Welcome IMAGE DECRIPTION: A bright, welcoming image with the Gold Pari logo and happy sports fans. CAPTION: Welcome to Gold Pari! Start your journey today. [https://goldpari.com/?tag=d_3556679m_69627] #GoldPari #Welcome
D27: Image | E27: 2. Football Post (Afternoon) COPY IN IMAGE: Champions League Qualifiers today—don’t miss the action! #GoldPari #ChampionsLeague IMAGE DECRIPTION: An action shot of a Champions League Qualifier match CAPTION: Who will advance? Bet on the Champions League Qualifiers now! #GoldPari #ChampionsLeague
D28: Image | E28: 3. Trivia Post (Evening) COPY IN IMAGE: Evening trivia! Which team has won the most UEFA Champions League titles? #GoldPari #FootballTrivia IMAGE DECRIPTION: A quiz card with a question about UEFA Champions League history. CAPTION: Test your football knowledge! Answer and let's have fun. #GoldPari #QuizTime
A30: 21st August | B30: Wednesday | C30: Whatsapp & Telegram | D30: Image | E30: 1. Welcome Post (Morning) COPY IN IMAGE: Good Morning, Ghana! Another day, another chance to win big with Gold Pari. #GoldPari #Welcome IMAGE DECRIPTION: A warm and inviting welcome image with the Gold Pari logo. CAPTION: Start your day with Gold Pari! https://goldpari.com/?tag=d_3556679m_69627] #GoldPari #Welcome
D31: Image | E31: 2. Betting odds (Midday) COPY IN IMAGE Get the best odds for Clampions league Qualifiers today on Gold Pari IMAGE DESCRIPTION The selected odds of the Clampions league Qualifiers CAPTION Our odds are your best chance to win #GoldPari #BestOdds
D32: Image | E32: 3. Engament Post (Afternoon) COPY IN IMAGE: Who won the inaugural UEFA Conference League? Comment to win a bonus! #GoldPari #FootballTrivia IMAGE DECRIPTION: A quiz card with a question about the UEFA Conference League. CAPTION: Test your football knowledge with GoldPari!. #GoldPari #QuizTime
D33: Image | E33: 4. Game Updates (Evening) COPY IN IMAGE: Stay updated on today's top matches #GoldPari #GameUpdates IMAGE DECRIPTION: A live scoreboard or image from the ended matches of the top leagues CAPTION: Get updates on tonight’s matches. #GoldPari #GameUpdates
A35: 22nd August | B35: Thursday | C35: Whatsapp & Telegram | D35: Image | E35: 1. Post (Morning) COPY IN IMAGE: IMAGE DECRIPTION: CAPTION:
D36: Image | E36: 2. Post (Midday) COPY IN IMAGE: IMAGE DECRIPTION: CAPTION:
D37: Image | E37: 2. Post (Afternoon) COPY IN IMAGE: IMAGE DECRIPTION: CAPTION:
D38: Image | E38: 2. Post (Evening) COPY IN IMAGE: IMAGE DECRIPTION: CAPTION:
A40: 23rd August | B40: FRIDAY | C40: Whatsapp & Telegram | D40: Image | E40: 1. Post (Morning) COPY IN IMAGE: IMAGE DECRIPTION: CAPTION:
D41: Image | E41: 2. Post (Afternoon) COPY IN IMAGE: IMAGE DECRIPTION: CAPTION:
D42: Image | E42: 2. Post (Evening) COPY IN IMAGE: IMAGE DECRIPTION: CAPTION:
A44: 24th August | B44: SATURDAY | C44: Whatsapp & Telegram | D44: Image | E44: 1. Post (Morning) COPY IN IMAGE: IMAGE DECRIPTION: CAPTION:
D45: Image | E45: 2. Post (Midday) COPY IN IMAGE: IMAGE DECRIPTION: CAPTION:
D46: Image | E46: 2. Post (Afternoon) COPY IN IMAGE: IMAGE DECRIPTION: CAPTION:
D47: Image | E47: 2. Post (Evening) COPY IN IMAGE: IMAGE DECRIPTION: CAPTION:
A49: 25th August | B49: SUNDAY | C49: Whatsapp & Telegram | D49: Image | E49: 1. Post (Morning) COPY IN IMAGE: IMAGE DECRIPTION: CAPTION:
D50: Image | E50: 2. Post (Midday) COPY IN IMAGE: IMAGE DECRIPTION: CAPTION:
...

Sheet Publishing Calendar - Nigeria
A1: Date | B1: Day | C1: Platform | D1: Content Type | E1: Post Description | F1: Content Creator | G1: Status | H1: Proposed Date | I1: Approval Date | J1: Publishing Time | K1: Link to Content | L1: Media File Link | M1: Notes
A2: 45534 | B2: Morning | C2: WhatsApp & Telegram | D2: Image Engagement | E2: MORNING [ INTRO ] COPY IN IMAGE Excited about the upcoming weekend fixtures —Gold Pari is here! Ready to turn your passion for sports into winnings? Join us now for the ultimate betting experience. #GoldPari #BetOnWinning!" IMAGE DESCRIPTION A Passionate demonstration of zeal, determination and happiness, with a dynamic overlay of Gold Pari's logo and a football in motion, symbolizing the start of a thrilling journey. CAPTION A NEW Gold is in TOWN!! 🌞 Gold Pari is here to kickstart your winning streak. Are you ready to bet on your passion? Start by visiting Gold Pari](https://goldpari.com/ and signing up to join the winning league. | F2: C.M | G2: Pending | H2: 45534 | I2: ----------------- | J2: 8:00am - 11:30am WAT
A3: 45534 | B3: Mid-day | C3: WhatsApp & Telegram | D3: Image Engagement | E3: 2. Awareness Post Midday COPY IN IMAGE Take a break and dive into the world of sports betting with Gold Pari. Big wins await you. SUPER EXCITED! #GoldPari #BettingMadeEasy IMAGE DESCRIPTION A Group of youth in similar indigious colors, with friends enjoying or hanging a sport arena while checking their phones, the Gold Pari app visible on the screen. CAPTION Midday thrill! As you enjoy your lunch, why not spice up your day with some winning bets? Join Gold Pari now and make every moment count! 🔗 [Insert Sign-Up Link] #GoldPari #LunchBreak #WinningStreak | F3: C.M | G3: Pending | H3: 45534 | I3: ------------- | J3: 12:00pm - 4:50pm WAT
A4: 45534 | B4: Evening | C4: WhatsApp & Telegram | D4: Image Engagement | E4: Engagement Post COPY IN IMAGE What’s your favourite sport to bet on? IMAGE DESCRIPTION A dynamic image Top Football League Logos together, with a subtle background of football favorite players in the various leagues, showcasing the variety of leagues available on Gold Pari. CAPTION What’s your favorite league to bet on? Let’s hear it in the comments! Share your picks and connect with other like minded people. [ Possibile Recap of the Weekly Betting Predictions and Interactions ] #GoldPari | F4: C.M | G4: Pending | H4: 45534 | I4: ----------------- | J4: 5:00pm - Dawn
A5: 45535 | B5: Morning | C5: WhatsApp & Telegram | D5: Image Engagement | E5: MORNING [ INTRO ] COPY IN IMAGE WEEKEND IS HERE! —Gold Pari is here! Ready to turn your passion for sports into winnings? Join us now for the ultimate betting experience. #GoldPari #BetOnWinning!" IMAGE DESCRIPTION Image of a Top Sport event for the Weekend with Time indication! The Particular Events Available for Selection on Gold Pari.com CAPTION A NEW Gold is in TOWN!! 🌞 Gold Pari is here to kickstart your winning streak. Are you ready to bet on your passion? Start by visiting Gold Pari](https://goldpari.com/ and signing up to join the winning league. | F5: C.M | G5: Pending | H5: 45535 | I5: ----------------- | J5: 8:00am - 11:30am WAT
A6: 45535 | B6: Mid-day | C6: WhatsApp & Telegram | D6: Image Engagement | E6: 2. Awareness Post Midday COPY IN IMAGE Take a break and dive into the world of sports betting with Gold Pari. Big wins await you. SUPER EXCITED! #GoldPari #BettingMadeEasy IMAGE DESCRIPTION A Group of youth in similar indigious colors, with friends enjoying or hanging a sport arena while checking their phones, the Gold Pari app visible on the screen. CAPTION Midday thrill! As you enjoy your lunch, why not spice up your day with some winning bets? Join Gold Pari now and make every moment count! 🔗 [Insert Sign-Up Link] #GoldPari #LunchBreak #WinningStreak | F6: C.M | G6: Pending | H6: 45535 | I6: ------------- | J6: 12:00pm - 4:50pm WAT
A7: 45535 | B7: Evening | C7: WhatsApp & Telegram | D7: Image Engagement | E7: Engagement Post COPY IN IMAGE What’s your favourite sport to bet on? IMAGE DESCRIPTION A Recap on the Weekend Top Predictions & site fixtures on Gold Pari Official Websites. CAPTION DO YOU KNOW! A Tip info on why Goldpari is the reliable sport platform, highlighting key websites fixtrures #GoldPari | F7: C.M | G7: Pending | H7: 45535 | I7: ----------------- | J7: 5:00pm - Dawn
A8: 45536 | B8: Morning | C8: WhatsApp & Telegram | D8: Image Engagement | E8: MORNING COPY IN IMAGE Start your day with excitement—Gold Pari is here! Ready to turn your passion for sports into winnings? Join us now for the ultimate betting experience. #GoldPari #BetOnWinning!" IMAGE DESCRIPTION A Passionate demonstration of zeal, determination and happiness, with a dynamic overlay of Gold Pari's logo and a football in motion, symbolizing the start of a thrilling journey. CAPTION A NEW Gold is in TOWN!! 🌞 Gold Pari is here to kickstart your winning streak. Are you ready to bet on your passion? Start by visiting Gold Pari](https://goldpari.com/ and signing up to join the winning league. | F8: C.M | G8: Pending | H8: 45536 | I8: ----------------- | J8: 8:00am - 11:30am WAT
A9: 45536 | B9: Mid-day | C9: WhatsApp & Telegram | D9: Image Engagement | E9: 2. Awareness Post Midday COPY IN IMAGE Take a break and dive into the world of sports betting with Gold Pari. Big wins await you. SUPER EXCITED! #GoldPari #BettingMadeEasy IMAGE DESCRIPTION A Group of youth in similar indigious colors, with friends enjoying or hanging a sport arena while checking their phones, the Gold Pari app visible on the screen. CAPTION Midday thrill! As you enjoy your lunch, why not spice up your day with some winning bets? Join Gold Pari now and make every moment count! 🔗 [Insert Sign-Up Link] #GoldPari #LunchBreak #WinningStreak | F9: C.M | G9: Pending | H9: 45536 | I9: ------------- | J9: 12:00pm - 4:50pm WAT
A10: 45536 | B10: Evening | C10: WhatsApp & Telegram | D10: Image Engagement | E10: Engagement Post COPY IN IMAGE What’s your favourite sport to bet on? IMAGE DESCRIPTION A dynamic image of a set of Top Leading Sport Professionals, with a subtle background of various sports icons, showcasing the variety of sports available on Gold Pari. CAPTION What’s your favorite sport to bet on? Let’s hear it in the comments! Share your picks and connect with other like minded people. [ Possibile Recap of the Weekly Betting Predictions and Interactions ] #GoldPari | F10: C.M | G10: Pending | H10: 45536 | I10: ----------------- | J10: 5:00pm - Dawn
A1007: 45541 | B1007: Morning | C1007: WhatsApp & Telegram | D1007: Image Engagement | E1007: MORNING COPY IN IMAGE WHO IS READY!!! International Friendly is Here— Gold Pari offers favourable odds on all international friendly matches ! Ready to turn your passion for sports into winnings? Join us now for the ultimate betting experience. #GoldPari #BetOnWinning!" IMAGE DESCRIPTION Image of Leading Africa Players Together with Gold Pari Logo. Showcase Few Teams to select during the international friendly week. CAPTION A NEW Gold is in TOWN!! 🌞 Gold Pari is here to kickstart your winning streak. Are you ready to bet on your passion? Start by visiting Gold Pari](https://goldpari.com/ and signing up to join the winning league. | F1007: C.M | G1007: Pending | H1007: 45549 | I1007: ----------------- | J1007: 8:00am - 11:30am WAT
A1008: 45537 | B1008: Morning | C1008: WhatsApp & Telegram | D1008: Image Engagement | E1008: MORNING COPY IN IMAGE WHO IS READY!!! International Friendly is Here— Gold Pari offers favourable odds on all international friendly matches ! Ready to turn your passion for sports into winnings? Join us now for the ultimate betting experience. #GoldPari #BetOnWinning!" IMAGE DESCRIPTION Image of Leading Africa Players Together with Gold Pari Logo. Showcase Few Teams to select during the international friendly week. CAPTION A NEW Gold is in TOWN!! 🌞 Gold Pari is here to kickstart your winning streak. Are you ready to bet on your passion? Start by visiting Gold Pari](https://goldpari.com/ and signing up to join the winning league. | F1008: C.M | G1008: Pending | H1008: 45549 | I1008: ----------------- | J1008: 8:00am - 11:30am WAT
A1009: 45542 | B1009: Morning | C1009: WhatsApp & Telegram | D1009: Image Engagement | E1009: MORNING [ INTRO ] COPY IN IMAGE Excited about the upcoming weekend fixtures —Gold Pari is here! Ready to turn your passion for sports into winnings? Join us now for the ultimate betting experience. #GoldPari #BetOnWinning!" IMAGE DESCRIPTION A Passionate demonstration of zeal, determination and happiness, with a dynamic overlay of Gold Pari's logo and a football in motion, symbolizing the start of a thrilling journey. CAPTION A NEW Gold is in TOWN!! 🌞 Gold Pari is here to kickstart your winning streak. Are you ready to bet on your passion? Start by visiting Gold Pari](https://goldpari.com/ and signing up to join the winning league. | F1009: C.M | G1009: Pending | H1009: 45549 | I1009: ----------------- | J1009: 8:00am - 11:30am WAT
... A1011: 45542 | B1011: Evening | C1011: WhatsApp & Telegram | D1011: Image Engagement | E1011: Engagement Post COPY IN IMAGE What’s your favourite sport to bet on? IMAGE DESCRIPTION A dynamic image Top Football League Logos together, with a subtle background of football favorite players in the various leagues, showcasing the variety of leagues available on Gold Pari. CAPTION What’s your favorite league to bet on? Let’s hear it in the comments! Share your picks and connect with other like minded people. [ Possibile Recap of the Weekly Betting Predictions and Interactions ] #GoldPari | F1011: C.M | G1011: Pending | H1011: 45534 | I1011: ----------------- | J1011: 5:00pm - Dawn

Sheet Publishing Calendar - Zambia
A1: Date | B1: Day | C1: Platform | D1: Content Type | E1: Post Description | F1: Content Creator | G1: Status | H1: Approval Date | I1: Publishing Time | J1: Link to Content | K1: Media File Link | L1: Notes

Sheet Publishing Tracking
A1: Date | B1: Country | C1: Channel | D1: Publishing | E1: Status
A2: 45528 | B2: Nigeria

Sheet Community Work Plan - Uganda 
A1: PROJECT PLAN: UGANDA | M1: =TODAY() -> 46325
B2: Planned start date | C2: MONDAY 15TH July, 2024 | E2: Planned end date 3 MONTHS | F2: October 15th, 2024. | H2: Planned Phase 1 Project Length (3 months ) | I2: 111 days
B5: Workstream:
B6: Lead:
B7: Task Description | C7: Owner | D7: Planned Start Date | E7: Planned End Date | F7: Dependencies | G7: Status | H7: Estimated Time to Complete (Days) | I7: Days to Start Date | J7: Actual Start Date | K7: Actual End Date | L7: Actual Time to Complete (Days) | M7: Notes/Links
G8: Not Started-Delayed | H8: =IF(D8="","N/A",(E8-D8+1)) -> N/A | I8: =IF(D8="","N/A",(D8-$M$1)) -> N/A | L8: =IF(J8="",0,(K8-J8+1)) -> 0
A9: A1 | G9: Not Started-Delayed | H9: =IF(D9="","N/A",(E9-D9+1)) -> N/A | I9: =IF(D9="","N/A",(D9-$M$1)) -> N/A | L9: =IF(J9="",0,(K9-J9+1)) -> 0
A10: A2 | G10: Not Started-Delayed | H10: =IF(D10="","N/A",(E10-D10+1)) -> N/A | I10: =IF(D10="","N/A",(D10-$M$1)) -> N/A | L10: =IF(J10="",0,(K10-J10+1)) -> 0
A11: A3 | G11: Not Started-Delayed | H11: =IF(D11="","N/A",(E11-D11+1)) -> N/A | I11: =IF(D11="","N/A",(D11-$M$1)) -> N/A | L11: =IF(J11="",0,(K11-J11+1)) -> 0
A12: A4 | G12: Not Started-Delayed | H12: =IF(D12="","N/A",(E12-D12+1)) -> N/A | I12: =IF(D12="","N/A",(D12-$M$1)) -> N/A | L12: =IF(J12="",0,(K12-J12+1)) -> 0
A13: A5 | G13: Not Started-Delayed | H13: =IF(D13="","N/A",(E13-D13+1)) -> N/A | I13: =IF(D13="","N/A",(D13-$M$1)) -> N/A | L13: =IF(J13="",0,(K13-J13+1)) -> 0
A14: A6 | G14: Not Started-Delayed | H14: =IF(D14="","N/A",(E14-D14+1)) -> N/A | I14: =IF(D14="","N/A",(D14-$M$1)) -> N/A | L14: =IF(J14="",0,(K14-J14+1)) -> 0
A15: A7 | G15: Scheduled | H15: =IF(D15="","N/A",(E15-D15+1)) -> N/A | I15: =IF(D15="","N/A",(D15-$M$1)) -> N/A | L15: =IF(J15="",0,(K15-J15+1)) -> 0
A16: A8 | G16: Scheduled | H16: =IF(D16="","N/A",(E16-D16+1)) -> N/A | I16: =IF(D16="","N/A",(D16-$M$1)) -> N/A | L16: =IF(J16="",0,(K16-J16+1)) -> 0
B19: Workstream:
B20: Lead:
B21: Task Description | C21: Owner | D21: Planned Start Date | E21: Planned End Date | F21: Dependencies | G21: Status | H21: Estimated Time to Complete (Days) | I21: Days to Start Date | J21: Actual Start Date | K21: Actual End Date | L21: Actual Time to Complete (Days) | M21: Notes/Links
A22: B1 | G22: Not Started-Delayed | H22: =IF(D22="","N/A",(E22-D22+1)) -> N/A | I22: =IF(D22="","N/A",(D22-$M$1)) -> N/A | L22: =IF(J22="",0,(K22-J22+1)) -> 0
A23: B2 | G23: Not Started-Delayed | H23: =IF(D23="","N/A",(E23-D23+1)) -> N/A | I23: =IF(D23="","N/A",(D23-$M$1)) -> N/A | L23: =IF(J23="",0,(K23-J23+1)) -> 0
A24: B3 | G24: Not Started-Delayed | H24: =IF(D24="","N/A",(E24-D24+1)) -> N/A | I24: =IF(D24="","N/A",(D24-$M$1)) -> N/A | L24: =IF(J24="",0,(K24-J24+1)) -> 0
A25: B4 | G25: Not Started-Delayed | H25: =IF(D25="","N/A",(E25-D25+1)) -> N/A | I25: =IF(D25="","N/A",(D25-$M$1)) -> N/A | L25: =IF(J25="",0,(K25-J25+1)) -> 0
A26: B5 | G26: Not Started-Delayed | H26: =IF(D26="","N/A",(E26-D26+1)) -> N/A | I26: =IF(D26="","N/A",(D26-$M$1)) -> N/A | L26: =IF(J26="",0,(K26-J26+1)) -> 0
A27: B6 | G27: Not Started-Delayed | H27: =IF(D27="","N/A",(E27-D27+1)) -> N/A | I27: =IF(D27="","N/A",(D27-$M$1)) -> N/A | L27: =IF(J27="",0,(K27-J27+1)) -> 0
A28: B7 | G28: Not Started-Delayed | H28: =IF(D28="","N/A",(E28-D28+1)) -> N/A | I28: =IF(D28="","N/A",(D28-$M$1)) -> N/A | L28: =IF(J28="",0,(K28-J28+1)) -> 0
A29: B8 | G29: Not Started-Delayed | H29: =IF(D29="","N/A",(E29-D29+1)) -> N/A | I29: =IF(D29="","N/A",(D29-$M$1)) -> N/A | L29: =IF(J29="",0,(K29-J29+1)) -> 0
A30: B9 | G30: Not Started-Delayed | H30: =IF(D30="","N/A",(E30-D30+1)) -> N/A | I30: =IF(D30="","N/A",(D30-$M$1)) -> N/A | L30: =IF(J30="",0,(K30-J30+1)) -> 0
A31: B10 | G31: Not Started-Delayed | H31: =IF(D31="","N/A",(E31-D31+1)) -> N/A | I31: =IF(D31="","N/A",(D31-$M$1)) -> N/A | L31: =IF(J31="",0,(K31-J31+1)) -> 0
A32: B11 | G32: Not Started-Delayed | H32: =IF(D32="","N/A",(E32-D32+1)) -> N/A | I32: =IF(D32="","N/A",(D32-$M$1)) -> N/A | L32: =IF(J32="",0,(K32-J32+1)) -> 0
A33: B12 | G33: Not Started-Delayed | H33: =IF(D33="","N/A",(E33-D33+1)) -> N/A | I33: =IF(D33="","N/A",(D33-$M$1)) -> N/A | L33: =IF(J33="",0,(K33-J33+1)) -> 0
A34: B13 | G34: Not Started-Delayed | H34: =IF(D34="","N/A",(E34-D34+1)) -> N/A | I34: =IF(D34="","N/A",(D34-$M$1)) -> N/A | L34: =IF(J34="",0,(K34-J34+1)) -> 0
B36: Workstream:
B37: Lead:
B38: Task Description | C38: Owner | D38: Planned Start Date | E38: Planned End Date | F38: Dependencies | G38: Status | H38: Estimated Time to Complete (Days) | I38: Days to Start Date | J38: Actual Start Date | K38: Actual End Date | L38: Actual Time to Complete (Days) | M38: Notes/Links
A39: C1 | H39: =IF(D39="","N/A",(E39-D39+1)) -> N/A | I39: =IF(D39="","N/A",(D39-$M$1)) -> N/A | L39: =IF(J39="",0,(K39-J39+1)) -> 0
A40: C2 | H40: =IF(D40="","N/A",(E40-D40+1)) -> N/A | I40: =IF(D40="","N/A",(D40-$M$1)) -> N/A | L40: =IF(J40="",0,(K40-J40+1)) -> 0
A41: C3 | H41: =IF(D41="","N/A",(E41-D41+1)) -> N/A | I41: =IF(D41="","N/A",(D41-$M$1)) -> N/A | L41: =IF(J41="",0,(K41-J41+1)) -> 0
A42: C4 | H42: =IF(D42="","N/A",(E42-D42+1)) -> N/A | I42: =IF(D42="","N/A",(D42-$M$1)) -> N/A | L42: =IF(J42="",0,(K42-J42+1)) -> 0
A43: C5 | H43: =IF(D43="","N/A",(E43-D43+1)) -> N/A | I43: =IF(D43="","N/A",(D43-$M$1)) -> N/A | L43: =IF(J43="",0,(K43-J43+1)) -> 0
A44: C7 | H44: =IF(D44="","N/A",(E44-D44+1)) -> N/A | I44: =IF(D44="","N/A",(D44-$M$1)) -> N/A | L44: =IF(J44="",0,(K44-J44+1)) -> 0
A45: C8 | H45: =IF(D45="","N/A",(E45-D45+1)) -> N/A | I45: =IF(D45="","N/A",(D45-$M$1)) -> N/A | L45: =IF(J45="",0,(K45-J45+1)) -> 0
...

Sheet Community Work Plan - Ghana
A1: PROJECT PLAN: GHANA | M1: =TODAY() -> 46325
B2: Planned start date | C2: MONDAY 15TH July, 2024 | E2: Planned end date 3 MONTHS | F2: October 15th, 2024. | H2: Planned Phase 1 Project Length (3 months ) | I2: 111 days
B5: Workstream:
B6: Lead:
B7: Task Description | C7: Owner | D7: Planned Start Date | E7: Planned End Date | F7: Dependencies | G7: Status | H7: Estimated Time to Complete (Days) | I7: Days to Start Date | J7: Actual Start Date | K7: Actual End Date | L7: Actual Time to Complete (Days) | M7: Notes/Links
G8: Not Started-Delayed | H8: =IF(D8="","N/A",(E8-D8+1)) -> N/A | I8: =IF(D8="","N/A",(D8-$M$1)) -> N/A | L8: =IF(J8="",0,(K8-J8+1)) -> 0
A9: A1 | G9: Not Started-Delayed | H9: =IF(D9="","N/A",(E9-D9+1)) -> N/A | I9: =IF(D9="","N/A",(D9-$M$1)) -> N/A | L9: =IF(J9="",0,(K9-J9+1)) -> 0
A10: A2 | G10: Not Started-Delayed | H10: =IF(D10="","N/A",(E10-D10+1)) -> N/A | I10: =IF(D10="","N/A",(D10-$M$1)) -> N/A | L10: =IF(J10="",0,(K10-J10+1)) -> 0
A11: A3 | G11: Not Started-Delayed | H11: =IF(D11="","N/A",(E11-D11+1)) -> N/A | I11: =IF(D11="","N/A",(D11-$M$1)) -> N/A | L11: =IF(J11="",0,(K11-J11+1)) -> 0
A12: A4 | G12: Not Started-Delayed | H12: =IF(D12="","N/A",(E12-D12+1)) -> N/A | I12: =IF(D12="","N/A",(D12-$M$1)) -> N/A | L12: =IF(J12="",0,(K12-J12+1)) -> 0
A13: A5 | G13: Not Started-Delayed | H13: =IF(D13="","N/A",(E13-D13+1)) -> N/A | I13: =IF(D13="","N/A",(D13-$M$1)) -> N/A | L13: =IF(J13="",0,(K13-J13+1)) -> 0
A14: A6 | G14: Not Started-Delayed | H14: =IF(D14="","N/A",(E14-D14+1)) -> N/A | I14: =IF(D14="","N/A",(D14-$M$1)) -> N/A | L14: =IF(J14="",0,(K14-J14+1)) -> 0
A15: A7 | G15: Scheduled | H15: =IF(D15="","N/A",(E15-D15+1)) -> N/A | I15: =IF(D15="","N/A",(D15-$M$1)) -> N/A | L15: =IF(J15="",0,(K15-J15+1)) -> 0
A16: A8 | G16: Scheduled | H16: =IF(D16="","N/A",(E16-D16+1)) -> N/A | I16: =IF(D16="","N/A",(D16-$M$1)) -> N/A | L16: =IF(J16="",0,(K16-J16+1)) -> 0
B19: Workstream:
B20: Lead:
B21: Task Description | C21: Owner | D21: Planned Start Date | E21: Planned End Date | F21: Dependencies | G21: Status | H21: Estimated Time to Complete (Days) | I21: Days to Start Date | J21: Actual Start Date | K21: Actual End Date | L21: Actual Time to Complete (Days) | M21: Notes/Links
A22: B1 | G22: Not Started-Delayed | H22: =IF(D22="","N/A",(E22-D22+1)) -> N/A | I22: =IF(D22="","N/A",(D22-$M$1)) -> N/A | L22: =IF(J22="",0,(K22-J22+1)) -> 0
A23: B2 | G23: Not Started-Delayed | H23: =IF(D23="","N/A",(E23-D23+1)) -> N/A | I23: =IF(D23="","N/A",(D23-$M$1)) -> N/A | L23: =IF(J23="",0,(K23-J23+1)) -> 0
A24: B3 | G24: Not Started-Delayed | H24: =IF(D24="","N/A",(E24-D24+1)) -> N/A | I24: =IF(D24="","N/A",(D24-$M$1)) -> N/A | L24: =IF(J24="",0,(K24-J24+1)) -> 0
A25: B4 | G25: Not Started-Delayed | H25: =IF(D25="","N/A",(E25-D25+1)) -> N/A | I25: =IF(D25="","N/A",(D25-$M$1)) -> N/A | L25: =IF(J25="",0,(K25-J25+1)) -> 0
A26: B5 | G26: Not Started-Delayed | H26: =IF(D26="","N/A",(E26-D26+1)) -> N/A | I26: =IF(D26="","N/A",(D26-$M$1)) -> N/A | L26: =IF(J26="",0,(K26-J26+1)) -> 0
A27: B6 | G27: Not Started-Delayed | H27: =IF(D27="","N/A",(E27-D27+1)) -> N/A | I27: =IF(D27="","N/A",(D27-$M$1)) -> N/A | L27: =IF(J27="",0,(K27-J27+1)) -> 0
A28: B7 | G28: Not Started-Delayed | H28: =IF(D28="","N/A",(E28-D28+1)) -> N/A | I28: =IF(D28="","N/A",(D28-$M$1)) -> N/A | L28: =IF(J28="",0,(K28-J28+1)) -> 0
A29: B8 | G29: Not Started-Delayed | H29: =IF(D29="","N/A",(E29-D29+1)) -> N/A | I29: =IF(D29="","N/A",(D29-$M$1)) -> N/A | L29: =IF(J29="",0,(K29-J29+1)) -> 0
A30: B9 | G30: Not Started-Delayed | H30: =IF(D30="","N/A",(E30-D30+1)) -> N/A | I30: =IF(D30="","N/A",(D30-$M$1)) -> N/A | L30: =IF(J30="",0,(K30-J30+1)) -> 0
A31: B10 | G31: Not Started-Delayed | H31: =IF(D31="","N/A",(E31-D31+1)) -> N/A | I31: =IF(D31="","N/A",(D31-$M$1)) -> N/A | L31: =IF(J31="",0,(K31-J31+1)) -> 0
A32: B11 | G32: Not Started-Delayed | H32: =IF(D32="","N/A",(E32-D32+1)) -> N/A | I32: =IF(D32="","N/A",(D32-$M$1)) -> N/A | L32: =IF(J32="",0,(K32-J32+1)) -> 0
A33: B12 | G33: Not Started-Delayed | H33: =IF(D33="","N/A",(E33-D33+1)) -> N/A | I33: =IF(D33="","N/A",(D33-$M$1)) -> N/A | L33: =IF(J33="",0,(K33-J33+1)) -> 0
A34: B13 | G34: Not Started-Delayed | H34: =IF(D34="","N/A",(E34-D34+1)) -> N/A | I34: =IF(D34="","N/A",(D34-$M$1)) -> N/A | L34: =IF(J34="",0,(K34-J34+1)) -> 0
B36: Workstream:
B37: Lead:
B38: Task Description | C38: Owner | D38: Planned Start Date | E38: Planned End Date | F38: Dependencies | G38: Status | H38: Estimated Time to Complete (Days) | I38: Days to Start Date | J38: Actual Start Date | K38: Actual End Date | L38: Actual Time to Complete (Days) | M38: Notes/Links
A39: C1 | H39: =IF(D39="","N/A",(E39-D39+1)) -> N/A | I39: =IF(D39="","N/A",(D39-$M$1)) -> N/A | L39: =IF(J39="",0,(K39-J39+1)) -> 0
A40: C2 | H40: =IF(D40="","N/A",(E40-D40+1)) -> N/A | I40: =IF(D40="","N/A",(D40-$M$1)) -> N/A | L40: =IF(J40="",0,(K40-J40+1)) -> 0
A41: C3 | H41: =IF(D41="","N/A",(E41-D41+1)) -> N/A | I41: =IF(D41="","N/A",(D41-$M$1)) -> N/A | L41: =IF(J41="",0,(K41-J41+1)) -> 0
A42: C4 | H42: =IF(D42="","N/A",(E42-D42+1)) -> N/A | I42: =IF(D42="","N/A",(D42-$M$1)) -> N/A | L42: =IF(J42="",0,(K42-J42+1)) -> 0
A43: C5 | H43: =IF(D43="","N/A",(E43-D43+1)) -> N/A | I43: =IF(D43="","N/A",(D43-$M$1)) -> N/A | L43: =IF(J43="",0,(K43-J43+1)) -> 0
A44: C7 | H44: =IF(D44="","N/A",(E44-D44+1)) -> N/A | I44: =IF(D44="","N/A",(D44-$M$1)) -> N/A | L44: =IF(J44="",0,(K44-J44+1)) -> 0
A45: C8 | H45: =IF(D45="","N/A",(E45-D45+1)) -> N/A | I45: =IF(D45="","N/A",(D45-$M$1)) -> N/A | L45: =IF(J45="",0,(K45-J45+1)) -> 0
...

Sheet Community Work Plan - Nigeria
A1: PROJECT PLAN: NIGERIA | M1: =TODAY() -> 46325
B2: Planned start date | C2: MONDAY 15TH July, 2024 | E2: Planned end date 3 MONTHS | F2: October 15th, 2024. | H2: Planned Phase 1 Project Length (3 months ) | I2: 111 days
B5: Workstream:
B6: Lead:
B7: Task Description | C7: Owner | D7: Planned Start Date | E7: Planned End Date | F7: Dependencies | G7: Status | H7: Estimated Time to Complete (Days) | I7: Days to Start Date | J7: Actual Start Date | K7: Actual End Date | L7: Actual Time to Complete (Days) | M7: Notes/Links
G8: Not Started-Delayed | H8: =IF(D8="","N/A",(E8-D8+1)) -> N/A | I8: =IF(D8="","N/A",(D8-$M$1)) -> N/A | L8: =IF(J8="",0,(K8-J8+1)) -> 0
A9: A1 | G9: Not Started-Delayed | H9: =IF(D9="","N/A",(E9-D9+1)) -> N/A | I9: =IF(D9="","N/A",(D9-$M$1)) -> N/A | L9: =IF(J9="",0,(K9-J9+1)) -> 0
A10: A2 | G10: Not Started-Delayed | H10: =IF(D10="","N/A",(E10-D10+1)) -> N/A | I10: =IF(D10="","N/A",(D10-$M$1)) -> N/A | L10: =IF(J10="",0,(K10-J10+1)) -> 0
A11: A3 | G11: Not Started-Delayed | H11: =IF(D11="","N/A",(E11-D11+1)) -> N/A | I11: =IF(D11="","N/A",(D11-$M$1)) -> N/A | L11: =IF(J11="",0,(K11-J11+1)) -> 0
A12: A4 | G12: Not Started-Delayed | H12: =IF(D12="","N/A",(E12-D12+1)) -> N/A | I12: =IF(D12="","N/A",(D12-$M$1)) -> N/A | L12: =IF(J12="",0,(K12-J12+1)) -> 0
A13: A5 | G13: Not Started-Delayed | H13: =IF(D13="","N/A",(E13-D13+1)) -> N/A | I13: =IF(D13="","N/A",(D13-$M$1)) -> N/A | L13: =IF(J13="",0,(K13-J13+1)) -> 0
A14: A6 | G14: Not Started-Delayed | H14: =IF(D14="","N/A",(E14-D14+1)) -> N/A | I14: =IF(D14="","N/A",(D14-$M$1)) -> N/A | L14: =IF(J14="",0,(K14-J14+1)) -> 0
A15: A7 | G15: Scheduled | H15: =IF(D15="","N/A",(E15-D15+1)) -> N/A | I15: =IF(D15="","N/A",(D15-$M$1)) -> N/A | L15: =IF(J15="",0,(K15-J15+1)) -> 0
A16: A8 | G16: Scheduled | H16: =IF(D16="","N/A",(E16-D16+1)) -> N/A | I16: =IF(D16="","N/A",(D16-$M$1)) -> N/A | L16: =IF(J16="",0,(K16-J16+1)) -> 0
B19: Workstream:
B20: Lead:
B21: Task Description | C21: Owner | D21: Planned Start Date | E21: Planned End Date | F21: Dependencies | G21: Status | H21: Estimated Time to Complete (Days) | I21: Days to Start Date | J21: Actual Start Date | K21: Actual End Date | L21: Actual Time to Complete (Days) | M21: Notes/Links
A22: B1 | G22: Not Started-Delayed | H22: =IF(D22="","N/A",(E22-D22+1)) -> N/A | I22: =IF(D22="","N/A",(D22-$M$1)) -> N/A | L22: =IF(J22="",0,(K22-J22+1)) -> 0
A23: B2 | G23: Not Started-Delayed | H23: =IF(D23="","N/A",(E23-D23+1)) -> N/A | I23: =IF(D23="","N/A",(D23-$M$1)) -> N/A | L23: =IF(J23="",0,(K23-J23+1)) -> 0
A24: B3 | G24: Not Started-Delayed | H24: =IF(D24="","N/A",(E24-D24+1)) -> N/A | I24: =IF(D24="","N/A",(D24-$M$1)) -> N/A | L24: =IF(J24="",0,(K24-J24+1)) -> 0
A25: B4 | G25: Not Started-Delayed | H25: =IF(D25="","N/A",(E25-D25+1)) -> N/A | I25: =IF(D25="","N/A",(D25-$M$1)) -> N/A | L25: =IF(J25="",0,(K25-J25+1)) -> 0
A26: B5 | G26: Not Started-Delayed | H26: =IF(D26="","N/A",(E26-D26+1)) -> N/A | I26: =IF(D26="","N/A",(D26-$M$1)) -> N/A | L26: =IF(J26="",0,(K26-J26+1)) -> 0
A27: B6 | G27: Not Started-Delayed | H27: =IF(D27="","N/A",(E27-D27+1)) -> N/A | I27: =IF(D27="","N/A",(D27-$M$1)) -> N/A | L27: =IF(J27="",0,(K27-J27+1)) -> 0
A28: B7 | G28: Not Started-Delayed | H28: =IF(D28="","N/A",(E28-D28+1)) -> N/A | I28: =IF(D28="","N/A",(D28-$M$1)) -> N/A | L28: =IF(J28="",0,(K28-J28+1)) -> 0
A29: B8 | G29: Not Started-Delayed | H29: =IF(D29="","N/A",(E29-D29+1)) -> N/A | I29: =IF(D29="","N/A",(D29-$M$1)) -> N/A | L29: =IF(J29="",0,(K29-J29+1)) -> 0
A30: B9 | G30: Not Started-Delayed | H30: =IF(D30="","N/A",(E30-D30+1)) -> N/A | I30: =IF(D30="","N/A",(D30-$M$1)) -> N/A | L30: =IF(J30="",0,(K30-J30+1)) -> 0
A31: B10 | G31: Not Started-Delayed | H31: =IF(D31="","N/A",(E31-D31+1)) -> N/A | I31: =IF(D31="","N/A",(D31-$M$1)) -> N/A | L31: =IF(J31="",0,(K31-J31+1)) -> 0
A32: B11 | G32: Not Started-Delayed | H32: =IF(D32="","N/A",(E32-D32+1)) -> N/A | I32: =IF(D32="","N/A",(D32-$M$1)) -> N/A | L32: =IF(J32="",0,(K32-J32+1)) -> 0
A33: B12 | G33: Not Started-Delayed | H33: =IF(D33="","N/A",(E33-D33+1)) -> N/A | I33: =IF(D33="","N/A",(D33-$M$1)) -> N/A | L33: =IF(J33="",0,(K33-J33+1)) -> 0
A34: B13 | G34: Not Started-Delayed | H34: =IF(D34="","N/A",(E34-D34+1)) -> N/A | I34: =IF(D34="","N/A",(D34-$M$1)) -> N/A | L34: =IF(J34="",0,(K34-J34+1)) -> 0
B36: Workstream:
B37: Lead:
B38: Task Description | C38: Owner | D38: Planned Start Date | E38: Planned End Date | F38: Dependencies | G38: Status | H38: Estimated Time to Complete (Days) | I38: Days to Start Date | J38: Actual Start Date | K38: Actual End Date | L38: Actual Time to Complete (Days) | M38: Notes/Links
A39: C1 | H39: =IF(D39="","N/A",(E39-D39+1)) -> N/A | I39: =IF(D39="","N/A",(D39-$M$1)) -> N/A | L39: =IF(J39="",0,(K39-J39+1)) -> 0
A40: C2 | H40: =IF(D40="","N/A",(E40-D40+1)) -> N/A | I40: =IF(D40="","N/A",(D40-$M$1)) -> N/A | L40: =IF(J40="",0,(K40-J40+1)) -> 0
A41: C3 | H41: =IF(D41="","N/A",(E41-D41+1)) -> N/A | I41: =IF(D41="","N/A",(D41-$M$1)) -> N/A | L41: =IF(J41="",0,(K41-J41+1)) -> 0
A42: C4 | H42: =IF(D42="","N/A",(E42-D42+1)) -> N/A | I42: =IF(D42="","N/A",(D42-$M$1)) -> N/A | L42: =IF(J42="",0,(K42-J42+1)) -> 0
A43: C5 | H43: =IF(D43="","N/A",(E43-D43+1)) -> N/A | I43: =IF(D43="","N/A",(D43-$M$1)) -> N/A | L43: =IF(J43="",0,(K43-J43+1)) -> 0
A44: C7 | H44: =IF(D44="","N/A",(E44-D44+1)) -> N/A | I44: =IF(D44="","N/A",(D44-$M$1)) -> N/A | L44: =IF(J44="",0,(K44-J44+1)) -> 0
A45: C8 | H45: =IF(D45="","N/A",(E45-D45+1)) -> N/A | I45: =IF(D45="","N/A",(D45-$M$1)) -> N/A | L45: =IF(J45="",0,(K45-J45+1)) -> 0
...

Sheet Community Work Plan - Zambia 
A1: PROJECT PLAN: Zambia | M1: =TODAY() -> 46325
B2: Planned start date | C2: MONDAY 15TH July, 2024 | E2: Planned end date 3 MONTHS | F2: October 15th, 2024. | H2: Planned Phase 1 Project Length (3 months ) | I2: 111 days
B5: Workstream:
B6: Lead:
B7: Task Description | C7: Owner | D7: Planned Start Date | E7: Planned End Date | F7: Dependencies | G7: Status | H7: Estimated Time to Complete (Days) | I7: Days to Start Date | J7: Actual Start Date | K7: Actual End Date | L7: Actual Time to Complete (Days) | M7: Notes/Links
G8: Not Started-Delayed | H8: =IF(D8="","N/A",(E8-D8+1)) -> N/A | I8: =IF(D8="","N/A",(D8-$M$1)) -> N/A | L8: =IF(J8="",0,(K8-J8+1)) -> 0
A9: A1 | G9: Not Started-Delayed | H9: =IF(D9="","N/A",(E9-D9+1)) -> N/A | I9: =IF(D9="","N/A",(D9-$M$1)) -> N/A | L9: =IF(J9="",0,(K9-J9+1)) -> 0
A10: A2 | G10: Not Started-Delayed | H10: =IF(D10="","N/A",(E10-D10+1)) -> N/A | I10: =IF(D10="","N/A",(D10-$M$1)) -> N/A | L10: =IF(J10="",0,(K10-J10+1)) -> 0
A11: A3 | G11: Not Started-Delayed | H11: =IF(D11="","N/A",(E11-D11+1)) -> N/A | I11: =IF(D11="","N/A",(D11-$M$1)) -> N/A | L11: =IF(J11="",0,(K11-J11+1)) -> 0
A12: A4 | G12: Not Started-Delayed | H12: =IF(D12="","N/A",(E12-D12+1)) -> N/A | I12: =IF(D12="","N/A",(D12-$M$1)) -> N/A | L12: =IF(J12="",0,(K12-J12+1)) -> 0
A13: A5 | G13: Not Started-Delayed | H13: =IF(D13="","N/A",(E13-D13+1)) -> N/A | I13: =IF(D13="","N/A",(D13-$M$1)) -> N/A | L13: =IF(J13="",0,(K13-J13+1)) -> 0
A14: A6 | G14: Not Started-Delayed | H14: =IF(D14="","N/A",(E14-D14+1)) -> N/A | I14: =IF(D14="","N/A",(D14-$M$1)) -> N/A | L14: =IF(J14="",0,(K14-J14+1)) -> 0
A15: A7 | G15: Scheduled | H15: =IF(D15="","N/A",(E15-D15+1)) -> N/A | I15: =IF(D15="","N/A",(D15-$M$1)) -> N/A | L15: =IF(J15="",0,(K15-J15+1)) -> 0
A16: A8 | G16: Scheduled | H16: =IF(D16="","N/A",(E16-D16+1)) -> N/A | I16: =IF(D16="","N/A",(D16-$M$1)) -> N/A | L16: =IF(J16="",0,(K16-J16+1)) -> 0
B19: Workstream:
B20: Lead:
B21: Task Description | C21: Owner | D21: Planned Start Date | E21: Planned End Date | F21: Dependencies | G21: Status | H21: Estimated Time to Complete (Days) | I21: Days to Start Date | J21: Actual Start Date | K21: Actual End Date | L21: Actual Time to Complete (Days) | M21: Notes/Links
A22: B1 | G22: Not Started-Delayed | H22: =IF(D22="","N/A",(E22-D22+1)) -> N/A | I22: =IF(D22="","N/A",(D22-$M$1)) -> N/A | L22: =IF(J22="",0,(K22-J22+1)) -> 0
A23: B2 | G23: Not Started-Delayed | H23: =IF(D23="","N/A",(E23-D23+1)) -> N/A | I23: =IF(D23="","N/A",(D23-$M$1)) -> N/A | L23: =IF(J23="",0,(K23-J23+1)) -> 0
A24: B3 | G24: Not Started-Delayed | H24: =IF(D24="","N/A",(E24-D24+1)) -> N/A | I24: =IF(D24="","N/A",(D24-$M$1)) -> N/A | L24: =IF(J24="",0,(K24-J24+1)) -> 0
A25: B4 | G25: Not Started-Delayed | H25: =IF(D25="","N/A",(E25-D25+1)) -> N/A | I25: =IF(D25="","N/A",(D25-$M$1)) -> N/A | L25: =IF(J25="",0,(K25-J25+1)) -> 0
A26: B5 | G26: Not Started-Delayed | H26: =IF(D26="","N/A",(E26-D26+1)) -> N/A | I26: =IF(D26="","N/A",(D26-$M$1)) -> N/A | L26: =IF(J26="",0,(K26-J26+1)) -> 0
A27: B6 | G27: Not Started-Delayed | H27: =IF(D27="","N/A",(E27-D27+1)) -> N/A | I27: =IF(D27="","N/A",(D27-$M$1)) -> N/A | L27: =IF(J27="",0,(K27-J27+1)) -> 0
A28: B7 | G28: Not Started-Delayed | H28: =IF(D28="","N/A",(E28-D28+1)) -> N/A | I28: =IF(D28="","N/A",(D28-$M$1)) -> N/A | L28: =IF(J28="",0,(K28-J28+1)) -> 0
A29: B8 | G29: Not Started-Delayed | H29: =IF(D29="","N/A",(E29-D29+1)) -> N/A | I29: =IF(D29="","N/A",(D29-$M$1)) -> N/A | L29: =IF(J29="",0,(K29-J29+1)) -> 0
A30: B9 | G30: Not Started-Delayed | H30: =IF(D30="","N/A",(E30-D30+1)) -> N/A | I30: =IF(D30="","N/A",(D30-$M$1)) -> N/A | L30: =IF(J30="",0,(K30-J30+1)) -> 0
A31: B10 | G31: Not Started-Delayed | H31: =IF(D31="","N/A",(E31-D31+1)) -> N/A | I31: =IF(D31="","N/A",(D31-$M$1)) -> N/A | L31: =IF(J31="",0,(K31-J31+1)) -> 0
A32: B11 | G32: Not Started-Delayed | H32: =IF(D32="","N/A",(E32-D32+1)) -> N/A | I32: =IF(D32="","N/A",(D32-$M$1)) -> N/A | L32: =IF(J32="",0,(K32-J32+1)) -> 0
A33: B12 | G33: Not Started-Delayed | H33: =IF(D33="","N/A",(E33-D33+1)) -> N/A | I33: =IF(D33="","N/A",(D33-$M$1)) -> N/A | L33: =IF(J33="",0,(K33-J33+1)) -> 0
A34: B13 | G34: Not Started-Delayed | H34: =IF(D34="","N/A",(E34-D34+1)) -> N/A | I34: =IF(D34="","N/A",(D34-$M$1)) -> N/A | L34: =IF(J34="",0,(K34-J34+1)) -> 0
B36: Workstream:
B37: Lead:
B38: Task Description | C38: Owner | D38: Planned Start Date | E38: Planned End Date | F38: Dependencies | G38: Status | H38: Estimated Time to Complete (Days) | I38: Days to Start Date | J38: Actual Start Date | K38: Actual End Date | L38: Actual Time to Complete (Days) | M38: Notes/Links
A39: C1 | H39: =IF(D39="","N/A",(E39-D39+1)) -> N/A | I39: =IF(D39="","N/A",(D39-$M$1)) -> N/A | L39: =IF(J39="",0,(K39-J39+1)) -> 0
A40: C2 | H40: =IF(D40="","N/A",(E40-D40+1)) -> N/A | I40: =IF(D40="","N/A",(D40-$M$1)) -> N/A | L40: =IF(J40="",0,(K40-J40+1)) -> 0
A41: C3 | H41: =IF(D41="","N/A",(E41-D41+1)) -> N/A | I41: =IF(D41="","N/A",(D41-$M$1)) -> N/A | L41: =IF(J41="",0,(K41-J41+1)) -> 0
A42: C4 | H42: =IF(D42="","N/A",(E42-D42+1)) -> N/A | I42: =IF(D42="","N/A",(D42-$M$1)) -> N/A | L42: =IF(J42="",0,(K42-J42+1)) -> 0
A43: C5 | H43: =IF(D43="","N/A",(E43-D43+1)) -> N/A | I43: =IF(D43="","N/A",(D43-$M$1)) -> N/A | L43: =IF(J43="",0,(K43-J43+1)) -> 0
A44: C7 | H44: =IF(D44="","N/A",(E44-D44+1)) -> N/A | I44: =IF(D44="","N/A",(D44-$M$1)) -> N/A | L44: =IF(J44="",0,(K44-J44+1)) -> 0
A45: C8 | H45: =IF(D45="","N/A",(E45-D45+1)) -> N/A | I45: =IF(D45="","N/A",(D45-$M$1)) -> N/A | L45: =IF(J45="",0,(K45-J45+1)) -> 0
...

Sheet Offline Activities 
A1: Note: Recruit 20 DSAs on 3 monthly contracts to focus on only pushing vendor acquisitions with a target of 20 merchants signing a day. | H1: Events Calendars - May to August 2023
A2: Pointers: | B2: The morning peak period (MPP) is the time interval from 6:00 a.m. - 9:00 a.m. | I2: Event | J2: Location | K2: Organizer | L2: Sponosorship offer | M2: Costs | N2: Acquired Results
B3: The evening peak period (EPP) is the time interval from 4:00 p.m. - 7:00 p.m.
B4: The off-peak period consists of three intervals: 12:00 pm. – 3:00 pm. | H4: 45052 | I4: Tubayoo Market Day | J4: Motiv - Industiral Area | K4: Tubayoo | L4: Financial Sponsorship/ Vendor Branding | M4: 1000000
A5: Targets- Growth Plan | H5: 45080 | I5: Tubayoo Market Day | J5: Motiv - Industiral Area | K5: Tubayoo | L5: Financial Sponsorship/ Vendor Branding | M5: 1000000
B6: Working Days/ Period | C6: Targets - Each | D6: Unit - Sales people | E6: Total Merchant Acquisitions | H6: 45108 | I6: Tubayoo Market Day | J6: Motiv - Industiral Area | K6: Tubayoo | L6: Financial Sponsorship/ Vendor Branding | M6: 1000000
B7: 94 Day - 15th May to 31st August (Execluding Sundays) | C7: 30 Merchants Onboarding | D7: 15 | E7: 37600 | H7: 45143 | I7: Tubayoo Market Day | J7: Motiv - Industiral Area | K7: Tubayoo | L7: Financial Sponsorship/ Vendor Branding | M7: 1000000
A9: Executions Highlights
B10: Identify and train a team of sales representatives
B11: Key marketing material messaging and positioning for the product
B12: Established sales targets and tracker for daily results
B13: Equip your sales team with uniforms & approach
B14: Track and measure your results
A16: Field Route Plan
A17: Date /Week | B17: Group | C17: Route | D17: Allocation | E17: Comments | F17: Feedback on location
A18: 15th May, 2023 | B18: A | C18: Gazaland - Downtown | D18: 10 Dsas | E18: Targetting downtown business centres | F18: - Electronics & Beauty
B19: B | C19: Mini Price | D19: 10 Dsas
A20: 22th May, 2023 | B20: A | C20: Jinja Raod | D20: 10 Dsas | E20: Targetting downtown business centres | F20: - Electronics & Beauty
B21: B | C21: Kitgum House - Mega Standard | D21: 10 Dsas
A22: 29th May, 2023 | B22: A | C22: Workers house | D22: 10 Dsas | E22: Targetting downtown business centres
B23: B | C23: Posta Uganda | D23: 10 Dsas
A24: 5th June 2023 | B24: A | C24: Workers house | D24: 10 Dsas | E24: Targetting downtown business centres
B25: B | C25: Crown House/ Communication House | D25: 10 Dsas
A26: 12th June 2023 | B26: A | C26: Kisenyi Business Center | D26: 10 Dsas | E26: Targetting downtown business centres
B27: B | C27: Mukwano Courts/ Luwum St, Kampala | D27: 10 Dsas
A28: 19th June 2023 | B28: A | C28: Wadegeya centres/ Kamokya | D28: 10 Dsas | E28: Targetting downtown business centres
B29: B | C29: Bukoto/kololo centres/ Acacia | D29: 10 Dsas
A30: 26th June 2023 | B30: A | C30: Wadegeya centres | D30: 10 Dsas | E30: Targetting downtown business centres
B31: B | C31: Bukoto/kololo centres | D31: 10 Dsas
A32: 3rd July 2023 | B32: A | C32: Nakawa/ Bugolobi | D32: 10 Dsas | E32: Targetting downtown business centres
B33: B | C33: Mbuaya/ Luzira | D33: 10 Dsas
A34: 10th July 2023 | B34: A | C34: Nakawa/ Bugolobi | D34: 10 Dsas | E34: Targetting downtown business centres
B35: B | C35: Mbuaya/ Luzira | D35: 10 Dsas
A36: 17th July 2023 | B36: A | C36: Kireka- Bweyogere | D36: 10 Dsas | E36: Targetting downtown business centres
B37: B | C37: Mbuaya/ Luzira | D37: 10 Dsas
A38: 24th July 2023 | B38: A | C38: Rubaga/ Mengo | D38: 10 Dsas | E38: Targetting downtown business centres
B39: B | C39: Rubaga/ Mengo | D39: 10 Dsas
A40: 31st July 2023 | B40: A | C40: Rubaga/ Mengo | D40: 10 Dsas | E40: Targetting downtown business centres
B41: B | C41: Rubaga/ Mengo | D41: 10 Dsas
A42: 31st July 2023 | B42: A | C42: Gayaza/ Katwee | D42: 10 Dsas | E42: Targetting downtown business centres
...

Sheet Kla Weekly Metrics
A1: Week | C1: =WEEKNUM(C2,2) -> 18 | D1: WoW Growth
A2: Metrics | B2: Definition | C2: 45040 | D2: =$JW$5/$JV$5-1 -> #DIV/0!
D3: =$JW$6/$JV$6-1 -> #DIV/0!

Sheet Kla - Monthly Metrics 
C1: =MONTH(C2) -> 1 | D1: MoM Growth
A2: Metrics | B2: Definition | C2: 43101
D3: =IFERROR(C3/B3-1,"")

Sheet Retention - Executions

Sheet Learnings - Feedback
A1: *** It's important to keep in mind that the details included in a customer feedback form may vary depending on the specific product or service being offered and the goals of the feedback collection process.
A2: ** To be populate by the costumer support associate or anyone getting feedback from customers
A4: Contact Information | B4: Transaction details | C4: Feedback Questions | D4: Ratings | E4: Comments or Suggestions: | F4: Consent:

Sheet Execution - Drive 
A1: *** Attach here links to all materials being used for the executions - to be used as reference to access all databases on artworks etc
